<?xml version="1.0"?>
<robot xmlns:xacro="http://www.ros.org/wiki/xacro">
    
    <xacro:macro name="diff_wheel" params="prefix parent x_reflect y_reflect">
        
        <link name="${prefix}_wheel">
            <visual>
                <geometry>
                    <cylinder radius="0.15" length="0.04"/>
                </geometry>
                <material name="dark_grey">
                    <color rgba="0.2 0.2 0.2 1.0"/>
                </material>
            </visual>
            <collision>
                <geometry>
                    <cylinder radius="0.15" length="0.04"/>
                </geometry>
            </collision>
            <inertial>
                <mass value="0.2"/>
                <inertia ixx="0.001" ixy="0" ixz="0" iyy="0.001" iyz="0" izz="0.001"/>
            </inertial>
        </link>

        <joint name="${prefix}_wheel_joint" type="continuous">
            <parent link="${parent}"/>
            <child link="${prefix}_wheel"/>
            <origin xyz="${x_reflect*0.1} ${y_reflect*0.12} 0" rpy="-1.5707 0 0"/>
            <axis xyz="0 0 1"/>
        </joint>

        <gazebo reference="${prefix}_wheel">
            <mu1>1.0</mu1>
            <mu2>1.0</mu2>
            <material>Gazebo/DarkGrey</material>
        </gazebo>

    </xacro:macro>
</robot>